#include<iostream>
using namespace std;

// 3. 예외가 발생해서 throw로 넘겼는데 try-catch가 없다면?

void Divide(int num1, int num2)
{
	if (num2 == 0)
		throw num2;
	cout << "나눗셈의 몫 : " << num1 / num2 << endl;
	cout << "나눗셈의 나머지 : " << num1 % num2 << endl;
}

int main(void)
{
	int num1, num2;
	cout << "두 개의 수 입력 : ";
	cin >> num1 >> num2;

	try
	{
		Divide(num1, num2);
		cout << "나눗셈을 마쳤습니다." << endl;
	}
	catch (int expn)
	{
		cout << "제수는 " << expn << "이 될 수 없습니다." << endl;
		cout << "프로그램을 다시 실행하세요." << endl;
	}

	// * 출력결과 1 *
	// 두 개의 수 입력 : 7 0
	// 제수는 0이 될 수 없습니다.
	// 프로그램을 다시 실행하세요.

	// * 출력결과 2 *
	// 두 개의 수 입력 : 100 3
	// 나눗셈의 몫 : 33
	// 나눗셈의 나머지 : 1
	// 나눗셈을 마쳤습니다.

	return 0;
}